Workbook

Sheet Sumar
A1: Sumar IOF vs. Centralizator oferta
A2: Text albastru = valori preluate din centralizatorul de oferta (input). Ore convertite la 8 ore/zi. Coloanele J–M se calculeaza din foaia IOF.
A4: Nr. | B4: Livrabil (cod IOF) | C4: Serviciu / Licenta | D4: Cant. oferta | E4: UM | F4: Tarif unitar oferta (EUR, fara TVA) | G4: Cost total oferta (EUR, fara TVA) | H4: Zile oferta (echiv. zile/om) | I4: Tarif echivalent (EUR/zi) | J4: Zile IOF | K4: Dif. zile (IOF - oferta) | L4: Valoare IOF (EUR) | M4: Dif. valoare (IOF - oferta)
A5: 1 | B5: 01 Migrare server | C5: Migrare Charisma ERP pe server nou | D5: 5 | E5: zile/om | F5: 700 | G5: =D5*F5 | H5: =IF(E5="ore",D5/8,D5) | I5: =IF(H5=0,0,G5/H5) | J5: =SUMIF(IOF!$B:$B,B5,IOF!$G:$G) | K5: =J5-H5 | L5: =SUMIF(IOF!$B:$B,B5,IOF!$X:$X) | M5: =L5-G5
A6: 2 | B6: 02 Portal Furnizori | C6: Portal Furnizori — Achizitii si Licitatii (Charisma BIZ) | D6: 35 | E6: zile/om | F6: — | G6: 24850 | H6: =IF(E6="ore",D6/8,D6) | I6: =IF(H6=0,0,G6/H6) | J6: =SUMIF(IOF!$B:$B,B6,IOF!$G:$G) | K6: =J6-H6 | L6: =SUMIF(IOF!$B:$B,B6,IOF!$X:$X) | M6: =L6-G6
A7: 3a | B7: 03a Invictus Sc.1 | C7: Integrare API Invictus Normare <-> Productie Charisma — Scenariul 1 (de baza, fara Planificare) | D7: 168 | E7: ore | F7: 87.5 | G7: =D7*F7 | H7: =IF(E7="ore",D7/8,D7) | I7: =IF(H7=0,0,G7/H7) | J7: =SUMIF(IOF!$B:$B,B7,IOF!$G:$G) | K7: =J7-H7 | L7: =SUMIF(IOF!$B:$B,B7,IOF!$X:$X) | M7: =L7-G7
A8: 3b | B8: 03b Invictus Planificare | C8: Integrare API Invictus — Supliment Scenariul 2 (Modul Planificare) | D8: 64 | E8: ore | F8: 87.5 | G8: =D8*F8 | H8: =IF(E8="ore",D8/8,D8) | I8: =IF(H8=0,0,G8/H8) | J8: =SUMIF(IOF!$B:$B,B8,IOF!$G:$G) | K8: =J8-H8 | L8: =SUMIF(IOF!$B:$B,B8,IOF!$X:$X) | M8: =L8-G8
A9: 4 | B9: 04 Payroll | C9: Integrare Date Salarizare / Bonuri de Masa -> Payroll Charisma | D9: 130 | E9: ore | F9: 80 | G9: =D9*F9 | H9: =IF(E9="ore",D9/8,D9) | I9: =IF(H9=0,0,G9/H9) | J9: =SUMIF(IOF!$B:$B,B9,IOF!$G:$G) | K9: =J9-H9 | L9: =SUMIF(IOF!$B:$B,B9,IOF!$X:$X) | M9: =L9-G9
A10: 5 | B10: 05 Etichete | C10: Generare si Transfer Automat Etichete per Lansare de Productie | D10: 20 | E10: zile/om | F10: 700 | G10: =D10*F10 | H10: =IF(E10="ore",D10/8,D10) | I10: =IF(H10=0,0,G10/H10) | J10: =SUMIF(IOF!$B:$B,B10,IOF!$G:$G) | K10: =J10-H10 | L10: =SUMIF(IOF!$B:$B,B10,IOF!$X:$X) | M10: =L10-G10
A11: 6 | B11: 06 PLM | C11: Integrare Aplicatie PLM externa <-> Charisma ERP | D11: 16 | E11: zile/om | F11: 700 | G11: =D11*F11 | H11: =IF(E11="ore",D11/8,D11) | I11: =IF(H11=0,0,G11/H11) | J11: =SUMIF(IOF!$B:$B,B11,IOF!$G:$G) | K11: =J11-H11 | L11: =SUMIF(IOF!$B:$B,B11,IOF!$X:$X) | M11: =L11-G11
A12: 7 | B12: 07 Magento | C12: Integrare API Magento <-> Stocuri / Vanzari Charisma ERP | D12: 28 | E12: zile/om | F12: 700 | G12: =D12*F12 | H12: =IF(E12="ore",D12/8,D12) | I12: =IF(H12=0,0,G12/H12) | J12: =SUMIF(IOF!$B:$B,B12,IOF!$G:$G) | K12: =J12-H12 | L12: =SUMIF(IOF!$B:$B,B12,IOF!$X:$X) | M12: =L12-G12
A13: Subtotal servicii — Poz. 1, 2, 3a, 4, 5, 6, 7 (Sc.1 fara Planificare): | G13: =SUM(G5:G12)-G8 | H13: =SUM(H5:H12)-H8 | J13: =SUM(J5:J12)-J8 | L13: =SUM(L5:L12)-L8
A14: Subtotal servicii — Poz. 1, 2, 3a+3b, 4, 5, 6, 7 (Sc.2 complet, recomandat): | G14: =SUM(G5:G12) | H14: =SUM(H5:H12) | J14: =SUM(J5:J12) | L14: =SUM(L5:L12)
A15: TOTAL GENERAL — Scenariul 2 complet (fara TVA): | G15: =G14 | L15: =L14
A16: TVA (cota in H16): | G16: =ROUND(G15*H16,0) | H16: 0.19 | L16: =ROUND(L15*H16,0)
A17: TOTAL GENERAL — Scenariul 2 complet (cu TVA): | G17: =G15+G16 | L17: =L15+L16
A19: Control IOF: total zile foaia IOF (rand total general) = | J19: =IOF!G87 | K19: =J19-J14

Sheet IOF
A1: Project plan | B1: Product | C1: WBS ID | D1: Activity | E1: Business Unit | F1: Licente (module + utilizatori) | G1: Effort | H1: Executive Director | I1: Integration PM | J1: Solution Manager | K1: BU Director | L1: Manager | M1: PM | N1: SR_BC | O1: EXP_BC | P1: JR_BC | Q1: SR_TC | R1: EXP_TC | S1: JR_TC | T1: TRA | U1: DEV | V1: Code factory DEV | W1: 3rd Party | X1: Valoare proiect | Y1: Project plan ERP | Z1: Observatii
X2: (EURO fara TVA)
A3: Livrabil | B3: 01 Migrare server (total) | C3: 01 | D3: 1. Migrare Charisma ERP pe server nou | G3: =SUBTOTAL(9,G4:G9) | H3: =SUBTOTAL(9,H4:H9) | I3: =SUBTOTAL(9,I4:I9) | J3: =SUBTOTAL(9,J4:J9) | K3: =SUBTOTAL(9,K4:K9) | L3: =SUBTOTAL(9,L4:L9) | M3: =SUBTOTAL(9,M4:M9) | N3: =SUBTOTAL(9,N4:N9) | ... X3: =SUBTOTAL(9,X4:X9) | Z3: Oferta: 5 zile/om x 700 EUR/zi
A4: 0.Project Management | B4: 01 Migrare server | C4: 01.01 | D4: Kick-off, planificare fereastra de migrare, coordonare cu IT client | G4: =SUM(H4:W4) | M4: 0.5 | X4: =G4*Sumar!$I$5 | Y4: 1.Project Setup
A5: 1.Design | B5: 01 Migrare server | C5: 01.02 | D5: Analiza infrastructura existenta si cerinte server nou (OS, SQL Server, dimensionare, backup) | G5: =SUM(H5:W5) | Q5: 0.5 | X5: =G5*Sumar!$I$5 | Y5: 2.Analysis and Design
A6: 4.Instalare | B6: 01 Migrare server | C6: 01.03 | D6: Instalare si configurare Charisma pe serverul nou (aplicatie, componente, servicii, licente) | G6: =SUM(H6:W6) | Q6: 1 | R6: 0.5 | X6: =G6*Sumar!$I$5 | Y6: 1.Project Setup
A7: 3.Import date | B7: 01 Migrare server | C7: 01.04 | D7: Migrare baze de date, job-uri, rapoarte, fisiere de configurare si integrari existente | G7: =SUM(H7:W7) | Q7: 1 | X7: =G7*Sumar!$I$5 | Y7: 3.Build
A8: 6.Testare | B8: 01 Migrare server | C8: 01.05 | D8: Testare post-migrare (conexiuni, performanta, fluxuri cheie, rapoarte) | G8: =SUM(H8:W8) | O8: 0.5 | R8: 0.5 | X8: =G8*Sumar!$I$5 | Y8: 4.Test & Training
A9: 7.Intrare in productie | B9: 01 Migrare server | C9: 01.06 | D9: Switch-over pe serverul nou si suport in prima zi de lucru | G9: =SUM(H9:W9) | Q9: 0.5 | X9: =G9*Sumar!$I$5 | Y9: 5.Go-Live & Hypercare
A10: Livrabil | B10: 02 Portal Furnizori (total) | C10: 02 | D10: 2. Portal Furnizori — Achizitii si Licitatii (Charisma BIZ) | F10: Charisma BIZ — Portal Furnizori (licenta inclusa in pret) | G10: =SUBTOTAL(9,G11:G23) | H10: =SUBTOTAL(9,H11:H23) | I10: =SUBTOTAL(9,I11:I23) | J10: =SUBTOTAL(9,J11:J23) | K10: =SUBTOTAL(9,K11:K23) | L10: =SUBTOTAL(9,L11:L23) | M10: =SUBTOTAL(9,M11:M23) | N10: =SUBTOTAL(9,N11:N23) | ... X10: =SUBTOTAL(9,X11:X23) | Z10: Oferta: 35 zile/om, pret pachet 24.850 EUR (implementare completa + integrare ERP, licenta inclusa)
A11: 0.Project Management | B11: 02 Portal Furnizori | C11: 02.01 | D11: Kick-off, plan proiect, status reports, project charter | G11: =SUM(H11:W11) | M11: 1 | N11: 1 | X11: =G11*Sumar!$I$6 | Y11: 1.Project Setup
A12: 0.Project Management | B12: 02 Portal Furnizori | C12: 02.02 | D12: Steering-uri, riscuri, aliniere interna | G12: =SUM(H12:W12) | M12: 1 | N12: 0.5 | X12: =G12*Sumar!$I$6 | Y12: 1.Project Setup
A13: 1.Design | B13: 02 Portal Furnizori | C13: 02.03 | D13: Workshop-uri de analiza flux achizitii si licitatii (cereri de oferta, evaluare, adjudecare) | G13: =SUM(H13:W13) | N13: 1.5 | O13: 1.5 | X13: =G13*Sumar!$I$6 | Y13: 2.Analysis and Design
A14: 1.Design | B14: 02 Portal Furnizori | C14: 02.04 | D14: Specificatie functionala, prezentare catre client, incorporare feedback | G14: =SUM(H14:W14) | N14: 1.5 | O14: 1 | Q14: 0.5 | X14: =G14*Sumar!$I$6 | Y14: 2.Analysis and Design
A15: 4.Instalare | B15: 02 Portal Furnizori | C15: 02.05 | D15: Instalare si configurare Charisma BIZ, publicare portal extern, securitate acces | G15: =SUM(H15:W15) | Q15: 1 | R15: 0.5 | X15: =G15*Sumar!$I$6 | Y15: 1.Project Setup
A16: 2.Configurari | B16: 02 Portal Furnizori | C16: 02.06 | D16: Configurare nomenclatoare, fluxuri de aprobare, roluri si drepturi utilizatori/furnizori | G16: =SUM(H16:W16) | N16: 1 | O16: 2 | Q16: 1 | R16: 1 | X16: =G16*Sumar!$I$6 | Y16: 3.Build
A17: 2.Configurari | B17: 02 Portal Furnizori | C17: 02.07 | D17: Configurare flux licitatii: cereri de oferta, grile de evaluare, adjudecare, notificari | G17: =SUM(H17:W17) | N17: 1.5 | O17: 2 | Q17: 1 | R17: 0.5 | X17: =G17*Sumar!$I$6 | Y17: 3.Build
A18: 2.Dezvoltare / Integrare | B18: 02 Portal Furnizori | C18: 02.08 | D18: Integrare ERP: sincronizare furnizori, articole, necesare si comenzi de aprovizionare | G18: =SUM(H18:W18) | Q18: 2 | R18: 1 | U18: 3 | X18: =G18*Sumar!$I$6 | Y18: 3.Build
A19: 3.Import date | B19: 02 Portal Furnizori | C19: 02.09 | D19: Import furnizori si date initiale, onboarding furnizori pe portal | G19: =SUM(H19:W19) | O19: 1 | R19: 0.5 | X19: =G19*Sumar!$I$6 | Y19: 3.Build
A20: 5.Training | B20: 02 Portal Furnizori | C20: 02.10 | D20: Training utilizatori interni + ghid de utilizare pentru furnizori | G20: =SUM(H20:W20) | N20: 0.5 | O20: 1.5 | X20: =G20*Sumar!$I$6 | Y20: 4.Test & Training
A21: 6.Testare | B21: 02 Portal Furnizori | C21: 02.11 | D21: Factory testing (portal + integrare ERP) | G21: =SUM(H21:W21) | O21: 1 | R21: 1 | X21: =G21*Sumar!$I$6 | Y21: 4.Test & Training
A22: 6.Testare | B22: 02 Portal Furnizori | C22: 02.12 | D22: Suport UAT si corectii | G22: =SUM(H22:W22) | N22: 0.5 | O22: 1 | X22: =G22*Sumar!$I$6 | Y22: 4.Test & Training
A23: 7.Intrare in productie | B23: 02 Portal Furnizori | C23: 02.13 | D23: Intrare in productie si asistenta pentru stabilizare | G23: =SUM(H23:W23) | O23: 0.5 | R23: 0.5 | X23: =G23*Sumar!$I$6 | Y23: 5.Go-Live & Hypercare
A24: Livrabil | B24: 03a Invictus Sc.1 (total) | C24: 03a | D24: 3a. Integrare API Invictus Normare <-> Productie Charisma — Scenariul 1 (de baza, fara Planificare) | G24: =SUBTOTAL(9,G25:G34) | H24: =SUBTOTAL(9,H25:H34) | I24: =SUBTOTAL(9,I25:I34) | J24: =SUBTOTAL(9,J25:J34) | K24: =SUBTOTAL(9,K25:K34) | L24: =SUBTOTAL(9,L25:L34) | M24: =SUBTOTAL(9,M25:M34) | N24: =SUBTOTAL(9,N25:N34) | ... X24: =SUBTOTAL(9,X25:X34) | Z24: Oferta: 168 ore max. x 87,50 EUR/ora (= 21 zile x 700 EUR/zi)
A25: 0.Project Management | B25: 03a Invictus Sc.1 | C25: 03a.01 | D25: Kick-off, coordonare cu furnizorul Invictus, status reports | G25: =SUM(H25:W25) | M25: 1 | N25: 0.5 | X25: =G25*Sumar!$I$7 | Y25: 1.Project Setup
A26: 1.Design | B26: 03a Invictus Sc.1 | C26: 03a.02 | D26: Analiza flux normare/productie si mapare date (norme, operatii, tehnologii, timpi) | G26: =SUM(H26:W26) | N26: 1 | Q26: 1.5 | X26: =G26*Sumar!$I$7 | Y26: 2.Analysis and Design
A27: 1.Design | B27: 03a Invictus Sc.1 | C27: 03a.03 | D27: Specificatie tehnica API (endpoint-uri, formate, autentificare, tratare erori) | G27: =SUM(H27:W27) | Q27: 1 | U27: 1 | X27: =G27*Sumar!$I$7 | Y27: 2.Analysis and Design
A28: 2.Dezvoltare / Integrare | B28: 03a Invictus Sc.1 | C28: 03a.04 | D28: Import norme, operatii si tehnologii din Invictus in Charisma | G28: =SUM(H28:W28) | Q28: 1 | U28: 3 | X28: =G28*Sumar!$I$7 | Y28: 3.Build
A29: 2.Dezvoltare / Integrare | B29: 03a Invictus Sc.1 | C29: 03a.05 | D29: Transfer comenzi / lansari de productie Charisma -> Invictus | G29: =SUM(H29:W29) | Q29: 1 | U29: 2.5 | X29: =G29*Sumar!$I$7 | Y29: 3.Build
A30: 2.Dezvoltare / Integrare | B30: 03a Invictus Sc.1 | C30: 03a.06 | D30: Preluare raportari de productie (realizari, timpi) Invictus -> Charisma | G30: =SUM(H30:W30) | Q30: 1 | U30: 2.5 | X30: =G30*Sumar!$I$7 | Y30: 3.Build
A31: 2.Dezvoltare / Integrare | B31: 03a Invictus Sc.1 | C31: 03a.07 | D31: Jurnalizare, monitorizare, tratare si reprocesare erori | G31: =SUM(H31:W31) | U31: 1.5 | X31: =G31*Sumar!$I$7 | Y31: 3.Build
A32: 6.Testare | B32: 03a Invictus Sc.1 | C32: 03a.08 | D32: Factory testing end-to-end | G32: =SUM(H32:W32) | Q32: 0.5 | R32: 1 | X32: =G32*Sumar!$I$7 | Y32: 4.Test & Training
A33: 6.Testare | B33: 03a Invictus Sc.1 | C33: 03a.09 | D33: Suport UAT si corectii | G33: =SUM(H33:W33) | N33: 0.5 | X33: =G33*Sumar!$I$7 | Y33: 4.Test & Training
A34: 7.Intrare in productie | B34: 03a Invictus Sc.1 | C34: 03a.10 | D34: Punere in productie si stabilizare | G34: =SUM(H34:W34) | Q34: 0.5 | X34: =G34*Sumar!$I$7 | Y34: 5.Go-Live & Hypercare
A35: Livrabil | B35: 03b Invictus Planificare (total) | C35: 03b | D35: 3b. Integrare API Invictus — Supliment Scenariul 2 (Modul Planificare) | G35: =SUBTOTAL(9,G36:G40) | H35: =SUBTOTAL(9,H36:H40) | I35: =SUBTOTAL(9,I36:I40) | J35: =SUBTOTAL(9,J36:J40) | K35: =SUBTOTAL(9,K36:K40) | L35: =SUBTOTAL(9,L36:L40) | M35: =SUBTOTAL(9,M36:M40) | N35: =SUBTOTAL(9,N36:N40) | ... X35: =SUBTOTAL(9,X36:X40) | Z35: Oferta: 64 ore max. x 87,50 EUR/ora (= 8 zile x 700 EUR/zi). Inclus in Scenariul 2 (recomandat)
A36: 1.Design | B36: 03b Invictus Planificare | C36: 03b.01 | D36: Analiza cerinte planificare (capacitati, calendar, prioritati) si mapare date | G36: =SUM(H36:W36) | N36: 0.5 | Q36: 1 | X36: =G36*Sumar!$I$8 | Y36: 2.Analysis and Design
A37: 2.Dezvoltare / Integrare | B37: 03b Invictus Planificare | C37: 03b.02 | D37: Transfer comenzi de planificat si capacitati Charisma -> Invictus | G37: =SUM(H37:W37) | Q37: 0.5 | U37: 1.5 | X37: =G37*Sumar!$I$8 | Y37: 3.Build
A38: 2.Dezvoltare / Integrare | B38: 03b Invictus Planificare | C38: 03b.03 | D38: Preluare plan de productie / secventiere Invictus -> Charisma (actualizare lansari, termene) | G38: =SUM(H38:W38) | Q38: 0.5 | U38: 2 | X38: =G38*Sumar!$I$8 | Y38: 3.Build
A39: 6.Testare | B39: 03b Invictus Planificare | C39: 03b.04 | D39: Testare scenarii de planificare | G39: =SUM(H39:W39) | Q39: 0.5 | R39: 0.5 | X39: =G39*Sumar!$I$8 | Y39: 4.Test & Training
A40: 5.Training | B40: 03b Invictus Planificare | C40: 03b.05 | D40: Training utilizatori planificare si intrare in productie | G40: =SUM(H40:W40) | N40: 0.5 | O40: 0.5 | X40: =G40*Sumar!$I$8 | Y40: 4.Test & Training
...
